Workbook
Name a: #REF!
Name alpha: #REF!
Name AR_ARB: 'WEIGHT TRANSFER MAIN'!$P$20
Name AR_FrontARB: 'WEIGHT TRANSFER MAIN'!$P$18
Name AR_FrontAxleAndTire: 'WEIGHT TRANSFER MAIN'!$P$50
Name AR_FrontSpring: 'WEIGHT TRANSFER MAIN'!$P$15
Name AR_RearARB: 'WEIGHT TRANSFER MAIN'!$P$19
Name AR_RearAxleAndTire: 'WEIGHT TRANSFER MAIN'!$P$51
Name AR_RearSpring: 'WEIGHT TRANSFER MAIN'!$P$16
Name AR_Spring: 'WEIGHT TRANSFER MAIN'!$P$17
Name AR_Total: 'WEIGHT TRANSFER MAIN'!$P$14
Name ARBMR_Fr: 'WEIGHT TRANSFER MAIN'!$E$37
Name ARBMR_Rr: 'WEIGHT TRANSFER MAIN'!$E$38
Name ARBStiffness_Fr: 'WEIGHT TRANSFER MAIN'!$E$31
Name ARBStiffness_Rr: 'WEIGHT TRANSFER MAIN'!$E$32
Name ARTotal_Tire: 'WEIGHT TRANSFER MAIN'!$P$40
Name b: #REF!
Name beta: #REF!
Name Cz: 'WEIGHT TRANSFER MAIN'!$E$42
Name DeltaZ: 'WEIGHT TRANSFER MAIN'!$P$27
Name DF: 'WEIGHT TRANSFER MAIN'!$E$47
Name DF_Dist: 'WEIGHT TRANSFER MAIN'!$E$43
Name FrontTrack: 'WEIGHT TRANSFER MAIN'!$E$7
Name FrontWheelRate_NoTire: 'WEIGHT TRANSFER MAIN'!$P$23
Name g_earth: 'LONGITUDINAL WEIGHT TRANSFER'!$C$42
Name gamma: #REF!
Name K: #REF!
Name LatAccel: 'WEIGHT TRANSFER MAIN'!$D$51
Name Long_Acc: 'LONGITUDINAL WEIGHT TRANSFER'!$D$36
Name MassCGHeight: 'WEIGHT TRANSFER MAIN'!$E$14
Name NSM_Fr: 'WEIGHT TRANSFER MAIN'!$E$11
Name NSM_Rr: 'WEIGHT TRANSFER MAIN'!$E$12
Name NSMCG_Fr: 'WEIGHT TRANSFER MAIN'!$E$15
Name NSMCG_Rr: 'WEIGHT TRANSFER MAIN'!$E$16
Name omega1: #REF!
Name omega2: #REF!
Name PCx: 'WEIGHT TRANSFER MAIN'!$E$22
Name PCy: 'WEIGHT TRANSFER MAIN'!$E$23
Name PCz: 'WEIGHT TRANSFER MAIN'!$E$24
Name Pitch_Moment: 'LONGITUDINAL WEIGHT TRANSFER'!$E$32
Name Pitch_Stiffness: 'WEIGHT TRANSFER MAIN'!$P$31
Name RC_Fr: 'WEIGHT TRANSFER MAIN'!$E$39
Name RC_Rr: 'WEIGHT TRANSFER MAIN'!$E$40
Name RearTrack: 'WEIGHT TRANSFER MAIN'!$E$8
Name RearWheelRate_NoTire: 'WEIGHT TRANSFER MAIN'!$P$24
Name Ro: 'WEIGHT TRANSFER MAIN'!$E$44
Name S: 'WEIGHT TRANSFER MAIN'!$E$45
Name SM: 'WEIGHT TRANSFER MAIN'!$E$17
Name SM_WD: 'WEIGHT TRANSFER MAIN'!$E$18
Name SMCGHeight: 'WEIGHT TRANSFER MAIN'!$E$21
Name Speed: 'WEIGHT TRANSFER MAIN'!$E$46
Name SpringMR_Fr: 'WEIGHT TRANSFER MAIN'!$E$35
Name SpringMR_Rr: 'WEIGHT TRANSFER MAIN'!$E$36
Name SpringStiffness_Fr: 'WEIGHT TRANSFER MAIN'!$E$27
Name SpringStiffness_Rr: 'WEIGHT TRANSFER MAIN'!$E$28
Name TireStiffness_Fr: 'WEIGHT TRANSFER MAIN'!$E$33
Name TireStiffness_Rr: 'WEIGHT TRANSFER MAIN'!$E$34
Name TotalMass: 'WEIGHT TRANSFER MAIN'!$E$9
Name WD: 'WEIGHT TRANSFER MAIN'!$E$10
Name Wheelbase: 'WEIGHT TRANSFER MAIN'!$E$6

Sheet HOW TO USE THIS TOOL
A6: 1) Inputs are in blue cells. Intermediate calculations and results in grey cells
A11: 2) ARB Stiffness can be defined as N/mm or N.m/deg by clicking on the unit cell
A16: 3) Vertical load (Fz) on each tire shown according to OptimumG color convention

Sheet WEIGHT TRANSFER MAIN
B5: INPUTS | H5: RESULTS SUMMARY | N5: RESULTS DETAILS
B6: Dim. | C6: Wheel base | E6: 1545 | F6: mm | H6: Roll | I6: Suspended mass roll stiffness | K6: =(E17*9.81*1*P27/1000)/P14 -> 0.30596157 | L6: °/g
C7: Front track | E7: 1248 | I7: Roll angle | K7: =K6*D51 -> 0.48953852 | L7: °Roll
C8: Rear track | E8: 1200 | H8: Damper | I8: Front Damper Force | K8: =(((V19/2)+(SM*SM_WD/100)/2))*g_earth*SpringMR_Fr -> 642.15642 | L8: N | N8: NO TIRE COUPLING
B9: Mass and Inertia | C9: Total mass | E9: 260 | F9: kg | I9: Rear Damper Force | K9: =(((V21/2)+(SM*(100-SM_WD)/100)/2)*g_earth)*SpringMR_Rr -> 634.01039 | N9: Roll | S9: Weight transfer
C10: Total Mass distribution | E10: 52 | F10: % Fr | I10: Front Damper Displacement | K10: =K8/SpringStiffness_Fr -> 14.669478 | L10: mm | N10: Roll angle due to lat G | P10: =P11/P14 -> 0.48953852 | Q10: ° | S10: Total W.T. | T10: Front
C11: Front non suspended mass (per wheel) | E11: 8 | F11: kg | I11: Rear Damper Displacement | K11: =K9/SpringStiffness_Rr -> 16.09286 | N11: Roll moment | P11: =E17*9.81*D51*P27/1000 -> 627.23727 | Q11: N.m | T11: Lateral | V11: =V15+V19+V23 -> 44.161017 | W11: kg
C12: Rear non suspended mass (per wheel) | E12: 8 | F12: kg | H12: M.N. | I12: 1st magic number | K12: =(P15+P18)/P14*100 -> 61.356885 | L12: N.m/N.m | N12: Roll Gradient | P12: =P10/LatAccel -> 0.30596157 | Q12: °/g | T12: Rear
C13: Non suspended mass weight distribution | E13: =E11/(E12+E11)*100 -> 50 | F13: % Fr | I13: 2nd magic number | T13: Lateral | V13: =V17+V21+V25 -> 34.499209 | W13: kg
C14: Total mass CG height | E14: 232 | F14: mm | I14: 3rd magic number | K14: =P50/P52*100 -> 58.633523 | N14: Anti-roll stiffness total | P14: =P17+P20 -> 1281.2828 | Q14: N.m/° | S14: NSM - W.T. | T14: Front
C15: Front non suspended mass CG height | E15: 203.2 | I15: 1st magic number | K15: =V19/(V19+V21)*100 -> 60.422913 | L15: kg/kg | N15: A-R stiffness coming from | O15: Front springs | P15: =((FrontTrack/1000)^2*TAN(RADIANS(1))*(FrontWheelRate_NoTire*1000))/2 -> 786.1552 | Q15: N.m/° | T15: Lateral | V15: =NSM_Fr*2*LatAccel*NSMCG_Fr/FrontTrack -> 4.1682051 | W15: kg
C16: Rear non suspended mass CG height | E16: 203.2 | I16: 2nd magic number | K16: =(V15+V19+V23)/(V11+V13)*100 -> 56.141482 | O16: Rear springs | P16: =((RearTrack/1000)^2*TAN(RADIANS(1))*RearWheelRate_NoTire*1000)/2 -> 495.12758 | Q16: N.m/° | T16: Rear
C17: Suspended mass | E17: =E9-2*E11-2*E12 -> 228 | F17: kg | I17: 3rd magic number | K17: =(V41+V45+V49)/(V37+V39)*100 -> 54.32916 | O17: Total | P17: =P15+P16 -> 1281.2828 | Q17: N.m/° | T17: Lateral | V17: =NSM_Rr*2*LatAccel*NSMCG_Rr/RearTrack -> 4.3349333 | W17: kg
C18: Suspended mass weight distribution | E18: =(E9*E10/100-E11*2)/E17*100 -> 52.280702 | F18: % Fr | N18: A-R stiffness coming from | O18: Front ARB | P18: =IF(F31="N.m/deg",ARBStiffness_Fr/ARBMR_Fr^2,(ARBStiffness_Fr*1000*(FrontTrack/1000)^2*TAN(RADIANS(1)))/ARBMR_Fr^2) -> 0 | Q18: N.m/° | S18: El. W.T. | T18: Front
C19: Suspended mass CG coordinates | D19: X | E19: =(100-E18)/100*E6 -> 737.26316 | F19: mm | H19: NO TIRE COUPLING | O19: Rear ARB | P19: =IF(F31="N.m/deg",ARBStiffness_Rr/ARBMR_Rr^2,(ARBStiffness_Rr*1000*(RearTrack/1000)^2*TAN(RADIANS(1)))/ARBMR_Rr^2) -> 0 | Q19: N.m/° | T19: Lateral | V19: =(SM*LatAccel*DeltaZ*(AR_FrontSpring+AR_FrontARB)/AR_Total)/FrontTrack -> 31.434863 | W19: kg
D20: Y | E20: 0 | O20: Total | P20: =P18+P19 -> 0 | Q20: N.m/° | T20: Rear
D21: Z | E21: =(E9*E14-(2*E11*E15+2*E12*E16))/E17 -> 236.04211 | I21: Dynamic Load (kg) | T21: Lateral | V21: =(SM*LatAccel*DeltaZ*(AR_RearSpring+AR_RearARB)/AR_Total)/RearTrack -> 20.589876 | W21: kg
C22: Pitch Center coordinates | D22: X | E22: 532.576 | F22: mm | I22: =TotalMass*WD/100*0.5+DF*DF_Dist/100/2-V11 -> 28.746294 | J22: =TotalMass*WD/100*0.5+DF*DF_Dist/100/2+V11 -> 117.06833 | N22: Additional values | S22: Geo. W.T. | T22: Front
D23: Y | E23: 0 | I23: =TotalMass*(100-WD)/100*0.5+DF*(100-DF_Dist)/100/2-V13 -> 34.131112 | J23: =TotalMass*(100-WD)/100*0.5+DF*(100-DF_Dist)/100/2+V13 -> 103.12953 | N23: Front wheel rate | P23: =E27/E35^2 -> 57.834588 | Q23: N/mm | T23: Lateral | V23: =SM*(SM_WD/100)*LatAccel*RC_Fr/FrontTrack -> 8.5579487 | W23: kg
D24: Z | E24: 29.632 | N24: Rear wheel rate | P24: =E28/E36^2 -> 39.397 | Q24: N/mm | T24: Rear
C25: Suspended mass roll inertia (ref SM CG) - Ixx | E25: 200 | F25: kg.m² | I25: Dynamic Load (N) | N25: Z Distance from SM CG to front roll axis | P25: =E21-E39 -> 180.04211 | Q25: mm | T25: Lateral | V25: =(SM*(100-SM_WD)/100)*LatAccel*RC_Rr/RearTrack -> 9.5744 | W25: kg
C26: Suspended mass pitch inertia (ref SM CG) - I | E26: 1250 | F26: kg.m² | I26: =9.81*(TotalMass*WD/100*0.5+DF*DF_Dist/100/2-V11) -> 282.00115 | J26: =9.81*(TotalMass*WD/100*0.5+DF*DF_Dist/100/2+V11) -> 1148.4403 | N26: Z Distance from SM CG to rear roll axis | P26: =E21-E40 -> 170.04211 | Q26: mm
B27: Spring ARB Tire | C27: Front spring stiffness | E27: 43.775 | F27: N/mm | I27: =9.81*(TotalMass*(100-WD)/100*0.5+DF*(100-DF_Dist)/100/2-V13) -> 334.82621 | J27: =9.81*(TotalMass*(100-WD)/100*0.5+DF*(100-DF_Dist)/100/2+V13) -> 1011.7007 | N27: Z Distance from SM CG to roll axis @ SM CG | P27: =E21-(((E40-E39)/E6*((100-E18)/100*E6))+E39) -> 175.27018 | Q27: mm
C28: Rear spring stiffness | E28: 39.397 | N28: Suspended mass inertia in roll - Iroll | P28: =E25+E17*(P27/1000)^2 -> 207.00408 | Q28: kg.m²
C29: Front SM Damping ratio @wheel | E29: 0.7 | N29: Distance between SM CG and Pitch Center | P29: =SQRT((E19-ABS(E22))^2+(SMCGHeight-E24)^2) -> 290.69222 | Q29: mm
C30: Rear SM Damping ratio @wheel | E30: 0.7 | H30: TIRE COUPLING | N30: Suspended mass inertia in pitch - Ipitch | P30: =E26+(SM*(P29/1000)^2) -> 1269.2664 | Q30: kg.m²
C31: Front ARB stiffness | E31: 0 | F31: N/mm | N31: Pitch Stiffness - Kpitch | P31: =((ABS(PCx)/1000)^2*(2*FrontWheelRate_NoTire*1000)+((Wheelbase-ABS(PCx))/1000)^2*(2*RearWheelRate_NoTire*1000))*PI()/180 -> 1982.2074 | Q31: Nm/deg
C32: Rear ARB stiffness | E32: 0 | I32: Dynamic Load (kg)
C33: Front tire stiffness | E33: 114 | F33: N/mm | I33: =TotalMass*WD/100*0.5+DF*DF_Dist/100/2-V37 -> 30.14155 | J33: =TotalMass*WD/100*0.5+DF*DF_Dist/100/2+V37 -> 115.67307
C34: Rear tire stiffness | E34: 114 | I34: =TotalMass*(100-WD)/100*0.5+DF*(100-DF_Dist)/100/2-V39 -> 32.680047 | J34: =TotalMass*(100-WD)/100*0.5+DF*(100-DF_Dist)/100/2+V39 -> 104.5806 | N34: TIRE COUPLING
B35: M.R. | C35: Front spring motion ratio | E35: 0.87 | F35: mm/mm | N35: Roll | S35: Weight transfer
C36: Rear spring motion ratio | E36: 1 | I36: Dynamic Load (N) | N36: Roll angle due to lat G | P36: =(P37/P40) -> 0.7051399 | Q36: ° | S36: Total W.T. | T36: Front
C37: Front anti roll bar motion ratio | E37: 1 | F37: =IF(F31="N.m/deg","deg/deg","mm/mm") -> mm/mm | I37: =9.81*(TotalMass*WD/100*0.5+DF*DF_Dist/100/2-V37) -> 295.6886 | J37: =9.81*(TotalMass*WD/100*0.5+DF*DF_Dist/100/2+V37) -> 1134.7528 | N37: Roll moment | P37: =E17*9.81*D51*P27/1000 -> 627.23727 | Q37: N.m | T37: Lateral | V37: =V41+V45+V49 -> 42.765761 | W37: kg
C38: Rear anti roll bar motion ratio | E38: 1 | I38: =9.81*(TotalMass*(100-WD)/100*0.5+DF*(100-DF_Dist)/100/2-V39) -> 320.59126 | J38: =9.81*(TotalMass*(100-WD)/100*0.5+DF*(100-DF_Dist)/100/2+V39) -> 1025.9357 | N38: Roll Gradient | P38: =P36/LatAccel -> 0.44071244 | Q38: °/g | T38: Rear
B39: Roll | C39: Front roll center height | E39: 56 | F39: mm | T39: Lateral | V39: =V43+V47+V51 -> 35.950275 | W39: kg
C40: Rear roll center height | E40: 66 | N40: Anti-roll moment total | P40: =P52 -> 889.52174 | Q40: N.m/° | S40: NSM - W.T. | T40: Front
N41: A-R moment coming from | O41: Front springs | P41: =((FrontTrack/1000)^2*TAN(RADIANS(1))*(FrontWheelRate_NoTire*1000))/2 -> 786.1552 | Q41: N.m/° | T41: Lateral | V41: =NSM_Fr*2*LatAccel*NSMCG_Fr/FrontTrack -> 4.1682051 | W41: kg
B42: Aero | C42: Down Force Coefficient | E42: 2.7 | F42: - | O42: Rear springs | P42: =((RearTrack/1000)^2*TAN(RADIANS(1))*RearWheelRate_NoTire*1000)/2 -> 495.12758 | Q42: N.m/° | T42: Rear
C43: Down Force Distribution | E43: 46 | F43: % Fr | O43: Total | P43: =P41+P42 -> 1281.2828 | Q43: N.m/° | T43: Lateral | V43: =NSM_Rr*2*LatAccel*NSMCG_Rr/RearTrack -> 4.3349333 | W43: kg
C44: Air Density | E44: 1.2255 | F44: kg/m3 | N44: A-R moment coming from | O44: Front ARB | P44: =IF(F31="N.m/deg",ARBStiffness_Fr/ARBMR_Fr^2,(ARBStiffness_Fr*1000*(FrontTrack/1000)^2*TAN(RADIANS(1)))/ARBMR_Fr^2) -> 0 | Q44: N.m/° | S44: El. W.T. | T44: Front
...

Sheet LONGITUDINAL WEIGHT TRANSFER
B5: WEIGHT TRANSFER | H5: NO TIRE COUPLING | M5: STATIC DISPLACEMENTS
B6: Total W.T. | M6: Front Wheel Vertical Displacement | P6: =(SM*SM_WD*9.8)/100*0.5/FrontWheelRate_NoTire -> 10.099147 | Q6: mm
C7: Longitudinal | E7: =E9+E11+E13 -> 39.042071 | F7: kg | I7: Dynamic Load (kg) | M7: Rear Wheel Vertical Displacement | P7: =(SM*(100-SM_WD)*9.8)/100*0.5/RearWheelRate_NoTire -> 13.531995
B8: NSM - W.T. | I8: =TotalMass*WD/100*0.5+DF*DF_Dist/100/2+E7/2 -> 92.428347 | J8: =TotalMass*WD/100*0.5+DF*DF_Dist/100/2+E7/2 -> 92.428347 | M8: Front Damper Displacement | P8: =P6/SpringMR_Fr -> 11.608215
C9: Longitudinal | E9: =(NSM_Fr+NSM_Rr)*2*Long_Acc*NSMCG_Fr/Wheelbase -> 4.2086731 | F9: kg | I9: =TotalMass*(100-WD)/100*0.5+DF*(100-DF_Dist)/100/2-E7/2 -> 49.109286 | J9: =TotalMass*(100-WD)/100*0.5+DF*(100-DF_Dist)/100/2-E7/2 -> 49.109286 | M9: Rear Damper Displacement | P9: =P7/SpringMR_Rr -> 13.531995
B10: El. W.T.
C11: Longitudinal | E11: =(SM*Long_Acc*(SMCGHeight-PCz)/Wheelbase) -> 30.46052 | F11: kg | I11: Dynamic Load (N)
B12: Geo. W.T. | I12: =I8*g_earth -> 905.7978 | J12: =J8*g_earth -> 905.7978 | M12: STATIC COILOEVER FORCES
C13: Longitudinal | E13: =SM*Long_Acc*PCz/Wheelbase -> 4.3728777 | F13: kg | I13: =I9*g_earth -> 481.271 | J13: =J9*g_earth -> 481.271 | M13: Front Damper | P13: =SpringStiffness_Fr*'LONGITUDINAL WEIGHT TRANSFER'!P8 -> 508.1496 | Q13: N
M14: Rear Damper | P14: =SpringStiffness_Rr*P9 -> 533.12
B15: DYNAMIC DISPLACEMENTS
C16: Front Wheel Vertical Displacement | E16: =E18*SpringMR_Fr -> 12.679896 | F16: mm
C17: Rear Wheel Vertical Displacement | E17: =E19*SpringMR_Rr -> 9.743469
C18: Front Damper Displacement | E18: =E28/SpringStiffness_Fr -> 14.574593
C19: Rear Damper Displacement | E19: =E29/SpringStiffness_Rr -> 9.743469
B21: DELTA DISPLACEMENTS
B22: Positive Compression | C22: Front Wheel | E22: =E16-P6 -> 2.5807489 | F22: mm
C23: Rear Wheel | E23: =E17-P7 -> -3.7885258
C24: Front Damper | E24: =E18-P8 -> 2.966378
C25: Rear Damper | E25: =E19-P9 -> -3.7885258
B27: COILOVER FORCES
C28: Front Damper | E28: =P13+((E11/2)*9.8)*SpringMR_Fr -> 638.0028 | F28: N
C29: Rear Damper | E29: =P14-((E11/2)*9.8)*SpringMR_Rr -> 383.86345
B31: PITCH MOMENT AND ANGLE
C32: Pitch Moment | E32: =Long_Acc*g_earth*SM*(SMCGHeight-PCz)/1000 -> 461.20274 | F32: N-m
C33: Pitch Angle | E33: =Pitch_Moment/Pitch_Stiffness -> 0.23267129 | F33: deg
B35: CASE TO SIMULATE
B36: Long G | D36: 1 | F36: G
B38: ERROR MESSAGE BOX
B39: =IF(OR(I8<0,I9<0,J8<0,J9<0),"One wheel is is the air! Calculations are false!","")
B42: g_earth | C42: 9.8 | D42: m/s^2
B43: NOTE: Braking G's are positive

Sheet DAMPING
B5: STIFFNESS AND DAMPING CONVERSIONS | H5: DAMPING CALCULATIONS NO TIRE COUPLING | N5: DAMPING CALCULATIONS WITH TIRE COUPLING
B6: Heave | C6: Front wheel rate from spring | E6: =SpringStiffness_Fr/SpringMR_Fr^2 -> 57.834588 | F6: N/mm | H6: Overall ride rate | I6: Total ride rate | K6: =E10*2+E11*2 -> 194.46318 | L6: N/mm | N6: Overall ride rate | O6: Total ride rate | Q6: =E12*2+E13*2 -> 135.29557 | R6: N/mm
C7: Rear wheel rate from spring | E7: =SpringStiffness_Rr/SpringMR_Rr^2 -> 39.397 | I7: Total sprung mass | K7: =SM -> 228 | L7: kg | O7: Total vehicle mass | Q7: =K7 -> 228 | R7: kg
C8: Front tire stiffness | E8: =TireStiffness_Fr -> 114 | F8: N/mm | I8: Ride natural frequency | K8: =SQRT((K6*1000)/K7)/(2*PI()) -> 4.6480565 | L8: Hz | O8: Ride natural frequency | Q8: =SQRT((Q6*1000)/Q7)/(2*PI()) -> 3.8769883 | R8: Hz
C9: Rear tire stiffness | E9: =TireStiffness_Rr -> 114 | I9: Ride total critical damping | K9: =2*SQRT(K6*1000*K7)/1000 -> 13.317298 | L9: Ns/mm | O9: Ride total critical damping | Q9: =2*SQRT(Q6*1000*Q7)/1000 -> 11.108085 | R9: Ns/mm
C10: Front ride rate without tire | E10: =E6 -> 57.834588 | F10: N/mm | I10: Actual ride damping | K10: =2*(E34+E35) -> 9.2975685 | L10: Ns/mm | O10: Actual ride damping | Q10: =2*(E34+E35) -> 9.2975685 | R10: Ns/mm
C11: Rear ride rate without tire | E11: =E7 -> 39.397 | I11: Actual overall damping ratio | K11: =K10/K9 -> 0.69815729 | O11: Actual overall damping ratio | Q11: =Q10/Q9 -> 0.83700911
C12: Front ride rate with tire | E12: =1/(1/E6+1/E8) -> 38.369127 | F12: N/mm | H12: Heave | I12: Front heave rate | K12: =E10*2 -> 115.66918 | L12: N/mm | N12: Heave | O12: Front heave rate | Q12: =E12*2 -> 76.738253 | R12: N/mm
C13: Rear ride rate with tire | E13: =1/(1/E7+1/E9) -> 29.278656 | I13: Rear heave rate | K13: =E11*2 -> 78.794 | O13: Rear heave rate | Q13: =E13*2 -> 58.557312
B14: Roll | C14: Front wheel rate from spring | E14: =E6 -> 57.834588 | F14: N/mm | I14: Front heave mass | K14: =SM*SM_WD/100 -> 119.2 | L14: kg | O14: Front heave mass | Q14: =K14 -> 119.2 | R14: kg
C15: Rear wheel rate from spring | E15: =E7 -> 39.397 | I15: Rear heave mass | K15: =SM*(100-SM_WD)/100 -> 108.8 | O15: Rear heave mass | Q15: =K15 -> 108.8
C16: Front wheel rate from ARB | E16: =IF('WEIGHT TRANSFER MAIN'!F31="N/mm",ARBStiffness_Fr/ARBMR_Fr^2*2,(ARBStiffness_Fr/ARBMR_Fr^2)*180/PI()*2/(FrontTrack/1000)^2/1000) -> 0 | F16: N/mm | I16: Front heave natural frequency | K16: =SQRT(K12*1000/K14)/(2*PI()) -> 4.9578208 | L16: Hz | O16: Front heave natural frequency | Q16: =SQRT(Q12*1000/Q14)/(2*PI()) -> 4.0382012 | R16: Hz
C17: Rear wheel rate from ARB | E17: =IF('WEIGHT TRANSFER MAIN'!F31="N/mm",ARBStiffness_Rr/ARBMR_Rr^2*2,(ARBStiffness_Rr/ARBMR_Rr^2)*180/PI()*2/(RearTrack/1000)^2/1000) -> 0 | I17: Rear heave natural frequency | K17: =SQRT(K13*1000/K15)/(2*PI()) -> 4.2830413 | O17: Rear heave natural frequency | Q17: =SQRT(Q13*1000/Q15)/(2*PI()) -> 3.6922938
C18: Front tire stiffness | E18: =E8 -> 114 | F18: N/mm | I18: Front heave critical damping | K18: =2*SQRT(K12*1000*K14)/1000 -> 7.4263762 | L18: Ns/mm | O18: Front heave critical damping per wheel | Q18: =2*SQRT(Q12*1000*Q14)/1000 -> 6.0488676 | R18: Ns/mm
C19: Rear tire stiffness | E19: =E9 -> 114 | I19: Rear heave critical damping | K19: =2*SQRT(K13*1000*K15)/1000 -> 5.8558645 | O19: Rear heave critical damping per wheel | Q19: =2*SQRT(Q13*1000*Q15)/1000 -> 5.0481821
C20: Front ride rate without tire | E20: =E14+E16 -> 57.834588 | F20: N/mm | I20: Actual front heave damping | K20: =E34*2 -> 5.1984633 | L20: Ns/mm | O20: Actual front heave damping | Q20: =K20 -> 5.1984633 | R20: Ns/mm
C21: Rear ride rate without tire | E21: =E15+E17 -> 39.397 | I21: Actual rear heave damping | K21: =E35*2 -> 4.0991051 | O21: Actual rear heave damping | Q21: =K21 -> 4.0991051
C22: Front ride rate with tire | E22: =1/(1/E20+1/E18) -> 38.369127 | F22: N/mm | I22: Actual front heave damping ratio | K22: =K20/K18 -> 0.7 | L22: Ns/mm | O22: Actual front heave damping ratio | Q22: =Q20/Q18 -> 0.859411 | R22: Ns/mm
C23: Rear ride rate with tire | E23: =1/(1/E21+1/E19) -> 29.278656 | I23: Actual rear heave damping ratio | K23: =K21/K19 -> 0.7 | O23: Actual rear heave damping ratio | Q23: =Q21/Q19 -> 0.81199629
C24: Front roll rate without tire | E24: =(FrontTrack/1000)^2*(E20*1000)/2*PI()/180 -> 786.07538 | F24: Nm/deg | H24: Roll | I24: Total roll rate | K24: =E24+E25 -> 1281.1527 | L24: Nm/deg | N24: Roll | O24: Total roll rate | Q24: =E26+E27 -> 889.43142 | R24: Nm/deg
C25: Rear roll rate without tire | E25: =(RearTrack/1000)^2*(E21*1000)/2*PI()/180 -> 495.0773 | I25: Roll inertia | K25: ='WEIGHT TRANSFER MAIN'!E25 -> 200 | L25: kg.m² | O25: Roll inertia | Q25: =K25 -> 200 | R25: kg.m²
C26: Front roll rate with tire | E26: =(FrontTrack/1000)^2*(E22*1000)/2*PI()/180 -> 521.50498 | F26: Nm/deg | I26: Roll natural frequency | K26: =SQRT(K24*180/PI()/K25)/(2*PI()) -> 3.0490665 | L26: Hz | O26: Roll natural frequency | Q26: =SQRT(Q24*180/PI()/Q25)/(2*PI()) -> 2.5405204 | R26: Hz
C27: Rear roll rate with tire | E27: =(RearTrack/1000)^2*(E23*1000)/2*PI()/180 -> 367.92644 | I27: Roll critical damping | K27: =2*SQRT(K24*180/PI()*K25)*PI()/180 -> 133.74702 | L27: Nms/deg | O27: Roll critical damping | Q27: =2*SQRT(Q24*180/PI()*Q25)*PI()/180 -> 111.43969 | R27: Nms/deg
B28: Pitch | C28: Front pitch rate without tire | E28: =((PCx)/1000)^2*(E10*1000)*PI()/180*2 -> 572.60903 | F28: Nm/deg | I28: Actual roll damping | K28: =E36+E37 -> 61.083639 | L28: Nms/deg | O28: Actual roll damping | Q28: =K28 -> 61.083639 | R28: Nms/deg
C29: Rear pitch rate without tire | E29: =((Wheelbase-PCx)/1000)^2*(E11*1000)*PI()/180*2 -> 1409.5983 | I29: Actual roll damping ratio | K29: =K28/K27 -> 0.45671027 | O29: Actual roll damping ratio | Q29: =Q28/Q27 -> 0.54813179
C30: Front pitch rate with tire | E30: =((PCx)/1000)^2*(E12*1000)*PI()/180*2 -> 379.88528 | F30: Nm/deg | H30: Pitch | I30: Total pitch rate | K30: =E28+E29 -> 1982.2074 | L30: Nm/deg | N30: Pitch | O30: Total pitch rate | Q30: =E30+E31 -> 1427.456 | R30: Nm/deg
C31: Rear pitch rate with tire | E31: =((Wheelbase-PCx)/1000)^2*(E13*1000)*PI()/180*2 -> 1047.5708 | I31: Pitch inertia | K31: ='WEIGHT TRANSFER MAIN'!E26 -> 1250 | L31: kg.m² | O31: Pitch inertia | Q31: =K31 -> 1250 | R31: kg.m²
B32: Damping | C32: Front damping ratio of heave | E32: ='WEIGHT TRANSFER MAIN'!E29 -> 0.7 | I32: Pitch natural frequency | K32: =SQRT(K30*180/PI()/K31)/(2*PI()) -> 1.5170538 | L32: Hz | O32: Pitch natural frequency | Q32: =SQRT(Q30*180/PI()/Q31)/(2*PI()) -> 1.2873831 | R32: Hz
C33: Rear damping ratio of heave | E33: ='WEIGHT TRANSFER MAIN'!E30 -> 0.7 | I33: Pitch critical damping | K33: =2*SQRT(K30*180/PI()*K31)*PI()/180 -> 415.90892 | L33: Nms/deg | O33: Pitch critical damping | Q33: =2*SQRT(Q30*180/PI()*Q31)*PI()/180 -> 352.94339 | R33: Nms/deg
C34: Front damping at wheel | E34: =E32*K18/2 -> 2.5992317 | F34: Ns/mm | I34: Actual pitch damping | K34: =E38+E39 -> 99.06611 | L34: Nms/deg | O34: Actual pitch damping | Q34: =K34 -> 99.06611 | R34: Nms/deg
C35: Rear damping at wheel | E35: =E33*K19/2 -> 2.0495526 | I35: Actual pitch damping ratio | K35: =K34/K33 -> 0.23819184 | O35: Actual pitch damping ratio | Q35: =Q34/Q33 -> 0.28068555
C36: Front roll damping | E36: =(E34*1000)*(FrontTrack/1000)^2/2*PI()/180 -> 35.328202 | F36: Nms/deg | N36: Unsprung Vibration | O36: Front wheel hop rate | Q36: =E10+E8 -> 171.83459 | R36: N/mm
C37: Rear roll damping | E37: =(E35*1000)*(RearTrack/1000)^2/2*PI()/180 -> 25.755437 | H37: TRANSIENT VEHICLE HANDLING | O37: Rear wheel hop rate | Q37: =E11+E9 -> 153.397
C38: Front pitch damping | E38: =((PCx)/1000)^2*(E34*1000)*PI()/180*2 -> 25.734488 | F38: Nm/deg | H38: Roll | I38: Roll damping distribution | K38: =E36/K28 -> 0.57835785 | L38: Front/rear | O38: Front unsprung mass | Q38: =NSM_Fr -> 8 | R38: kg
C39: Rear pitch damping | E39: =((Wheelbase-PCx)/1000)^2*(E35*1000)*PI()/180*2 -> 73.331622 | O39: Rear unsprung mass | Q39: =NSM_Rr -> 8
O40: Front wheel hop natural freq | Q40: =SQRT(Q36*1000/Q38)/(2*PI()) -> 23.325472 | R40: Hz
O41: Rear wheel hop natural freq | Q41: =SQRT(Q37*1000/Q39)/(2*PI()) -> 22.038578
O42: Front wheel hop critical damping | Q42: =2*SQRT(Q36*1000*Q38)/1000 -> 2.3449322 | R42: Ns/mm
O43: Rear wheel hop critical damping | Q43: =2*SQRT(Q37*1000*Q39)/1000 -> 2.2155595
O44: Actual front wheel hop damping | Q44: =E34 -> 2.5992317 | R44: Ns/mm
...

Sheet DAMPING RATIO TRADE-OFF
B6: INPUT IDEAL DAMPING RATIO | D6: 0.7
B8: Damping Matrix | D8: DAMPING RATIO
B9: Without Tire Coupling | D9: Ride | E9: Front Heave | F9: Rear Heave | G9: Roll | H9: Pitch
B10: Critically Damped Mode | C10: Ride | D10: =D6 -> 0.7 | E10: =D61/DAMPING!$K$18 -> 0.70184757 | F10: =E61/DAMPING!$K$19 -> 0.70184757 | G10: =(J61+K61)/DAMPING!$K$27 -> 0.45791571 | H10: =(L61+M61)/DAMPING!$K$33 -> 0.23882052
C11: Front Heave | D11: =(G62+H62)*2/DAMPING!$K$9 -> 0.69815729 | E11: =D6 -> 0.7 | F11: =E62/DAMPING!$K$19 -> 0.7 | G11: =(J62+K62)/DAMPING!$K$27 -> 0.45671027 | H11: =(L62+M62)/DAMPING!$K$33 -> 0.23819184
C12: Rear Heave | D12: =(G63+H63)*2/DAMPING!$K$9 -> 0.69815729 | E12: =D63/DAMPING!$K$18 -> 0.7 | F12: =D6 -> 0.7 | G12: =(J63+K63)/DAMPING!$K$27 -> 0.45671027 | H12: =(L63+M63)/DAMPING!$K$33 -> 0.23819184
C13: Roll | D13: =(G64+H64)*2/DAMPING!$K$9 -> 1.0700659 | E13: =D64/DAMPING!$K$18 -> 1.0728903 | F13: =E64/DAMPING!$K$19 -> 1.0728903 | G13: =D6 -> 0.7 | H13: =(L64+M64)/DAMPING!$K$33 -> 0.36507672
C14: Pitch | D14: =(G65+H65)*2/DAMPING!$K$9 -> 2.05175 | E14: =D65/DAMPING!$K$18 -> 2.0571653 | F14: =E65/DAMPING!$K$19 -> 2.0571653 | G14: =(J65+K65)/DAMPING!$K$27 -> 1.3421836 | H14: =D6 -> 0.7
B16: Damping Matrix | D16: DAMPING RATIO
B17: With Tire Coupling | D17: Ride | E17: Front Heave | F17: Rear Heave | G17: Roll | H17: Pitch | I17: Front Wheel Hop | J17: Rear Wheel Hop
B18: Critically Damped Mode | C18: Ride | D18: =D6 -> 0.7 | E18: =D69/DAMPING!$Q$18 -> 0.71873495 | F18: =E69/DAMPING!$Q$19 -> 0.6790815 | G18: =(J69+K69)/DAMPING!$Q$27 -> 0.45840869 | H18: =(L69+M69)/DAMPING!$Q$33 -> 0.23474044 | I18: =G69/DAMPING!$Q$42 -> 0.92700604 | J18: =H69/DAMPING!$Q$43 -> 0.77364815
C19: Front Heave | D19: =(G70+H70)*2/DAMPING!$K$9 -> 0.56865703 | E19: =D18 -> 0.7 | F19: =E70/DAMPING!$Q$19 -> 0.66138019 | G19: =(J70+K70)/DAMPING!$Q$27 -> 0.44645956 | H19: =(L70+M70)/DAMPING!$Q$33 -> 0.22862156 | I19: =G70/DAMPING!$Q$42 -> 0.90284218 | J19: =H70/DAMPING!$Q$43 -> 0.75348181
C20: Rear Heave | D20: =(G71+H71)*2/DAMPING!$K$9 -> 0.60186248 | E20: =D71/DAMPING!$Q$18 -> 0.74087493 | F20: =E19 -> 0.7 | G20: =(J71+K71)/DAMPING!$Q$27 -> 0.47252956 | H20: =(L71+M71)/DAMPING!$Q$33 -> 0.24197141 | I20: =G71/DAMPING!$Q$42 -> 0.95556162 | J20: =H71/DAMPING!$Q$43 -> 0.79747969
C21: Roll | D21: =(G72+H72)*2/DAMPING!$K$9 -> 0.89159234 | E21: =D72/DAMPING!$Q$18 -> 1.0975238 | F21: =E72/DAMPING!$Q$19 -> 1.0369722 | G21: =F20 -> 0.7 | H21: =(L72+M72)/DAMPING!$Q$33 -> 0.35845373 | I21: =G72/DAMPING!$Q$42 -> 1.4155583 | J21: =H72/DAMPING!$Q$43 -> 1.1813775
C22: Pitch | D22: =(G73+H73)*2/DAMPING!$K$9 -> 1.7411303 | E22: =D73/DAMPING!$Q$18 -> 2.1432799 | F22: =E73/DAMPING!$Q$19 -> 2.0250327 | G22: =(J73+K73)/DAMPING!$Q$27 -> 1.3669826 | H22: =G21 -> 0.7 | I22: =G73/DAMPING!$Q$42 -> 2.7643479 | J22: =H73/DAMPING!$Q$43 -> 2.307032
C23: Front Wheel Hop | D23: =(G74+H74)*2/DAMPING!$K$9 -> 0.62985208 | E23: =D74/DAMPING!$Q$18 -> 0.77532931 | F23: =E74/DAMPING!$Q$19 -> 0.73255349 | G23: =(J74+K74)/DAMPING!$Q$27 -> 0.49450454 | H23: =G22 -> 1.3669826 | I23: 1 | J23: =H74/DAMPING!$Q$43 -> 0.83456647
C24: Rear Wheel Hop | D24: =(G75+H75)*2/DAMPING!$K$9 -> 0.75470572 | E24: =D75/DAMPING!$Q$18 -> 0.92902044 | F24: =E75/DAMPING!$Q$19 -> 0.8777653 | G24: =(J75+K75)/DAMPING!$Q$27 -> 0.59252865 | H24: =G23 -> 0.49450454 | I24: =G75/DAMPING!$Q$42 -> 1.1982269 | J24: 1
D59: Per end | G59: Per Wheel | J59: Roll Damping | L59: Pitch Damping
B60: Actual Damping | D60: Front Damping | E60: Rear Damping | G60: Front Damping | H60: Rear Damping | J60: Front | K60: Rear | L60: Front | M60: Rear
B61: =DAMPING!$K$9*D10 -> 9.3221084 | C61: Ns/mm | D61: =B61*DAMPING!$K$20/(DAMPING!$K$20+DAMPING!$K$21) -> 5.2121841 | E61: =B61*DAMPING!$K$21/(DAMPING!$K$20+DAMPING!$K$21) -> 4.1099243 | F61: Ns/mm | G61: =D61/2 -> 2.6060921 | H61: =E61/2 -> 2.0549621 | I61: Ns/mm | J61: =G61*PI()/180*(FrontTrack/1000)^2*1000/2 -> 35.421447 | K61: =H61*PI()/180*(RearTrack/1000)^2*1000/2 -> 25.823416 | L61: =((PCx)/1000)^2*(G61*1000)*PI()/180*2 -> 25.802412 | M61: =((Wheelbase-PCx)/1000)^2*(H61*1000)*PI()/180*2 -> 73.525172 | N61: Nms/deg
B62: =DAMPING!$K$18*E11 -> 5.1984633 | C62: Ns/mm | D62: =B62 -> 5.1984633 | E62: =D62*DAMPING!$K$21/DAMPING!$K$20 -> 4.0991051 | F62: Ns/mm | G62: =D62/2 -> 2.5992317 | H62: =E62/2 -> 2.0495526 | I62: Ns/mm | J62: =G62*PI()/180*(FrontTrack/1000)^2*1000/2 -> 35.328202 | K62: =H62*PI()/180*(RearTrack/1000)^2*1000/2 -> 25.755437 | L62: =((PCx)/1000)^2*(G62*1000)*PI()/180*2 -> 25.734488 | M62: =((Wheelbase-PCx)/1000)^2*(H62*1000)*PI()/180*2 -> 73.331622 | N62: Nms/deg
B63: =DAMPING!$K$19*F12 -> 4.0991051 | C63: Ns/mm | D63: =E63/DAMPING!$K$21*DAMPING!$K$20 -> 5.1984633 | E63: =B63 -> 4.0991051 | F63: Ns/mm | G63: =D63/2 -> 2.5992317 | H63: =E63/2 -> 2.0495526 | I63: Ns/mm | J63: =G63*PI()/180*(FrontTrack/1000)^2*1000/2 -> 35.328202 | K63: =H63*PI()/180*(RearTrack/1000)^2*1000/2 -> 25.755437 | L63: =((PCx)/1000)^2*(G63*1000)*PI()/180*2 -> 25.734488 | M63: =((Wheelbase-PCx)/1000)^2*(H63*1000)*PI()/180*2 -> 73.331622 | N63: Nms/deg
B64: =DAMPING!$K$27*G13 -> 93.622916 | C64: Nms/deg | D64: =G64*2 -> 7.9676867 | E64: =H64*2 -> 6.2826999 | F64: Ns/mm | G64: =J64*180/PI()*2/(FrontTrack/1000)^2/1000 -> 3.9838433 | H64: =K64*180/PI()*2/(RearTrack/1000)^2/1000 -> 3.14135 | I64: Ns/mm | J64: =B64*DAMPING!$E$36/(DAMPING!$E$36+DAMPING!$E$37) -> 54.147548 | K64: =B64*DAMPING!$E$37/(DAMPING!$E$36+DAMPING!$E$37) -> 39.475368 | L64: =((PCx)/1000)^2*(G64*1000)*PI()/180*2 -> 39.443259 | M64: =((Wheelbase-PCx)/1000)^2*(H64*1000)*PI()/180*2 -> 112.3954 | N64: Nms/deg
B65: =DAMPING!$K$33*H14 -> 291.13624 | C65: Nms/deg | D65: =G65*2 -> 15.277284 | E65: =H65*2 -> 12.046481 | F65: Ns/mm | G65: =L65*180/PI()/(PCx/1000)^2/1000/2 -> 7.6386419 | H65: =M65*180/PI()/((Wheelbase-PCx)/1000)^2/1000/2 -> 6.0232407 | I65: Ns/mm | J65: =G65*PI()/180*(FrontTrack/1000)^2*1000/2 -> 103.82279 | K65: =H65*PI()/180*(RearTrack/1000)^2*1000/2 -> 75.690276 | L65: =B65*(DAMPING!$E$38/(DAMPING!$E$39+DAMPING!$E$38)) -> 75.628711 | M65: =B65*DAMPING!$E$39/(DAMPING!$E$38+DAMPING!$E$39) -> 215.50753 | N65: Nms/deg
D67: Per end | G67: Per Wheel | J67: Roll Damping | L67: Pitch Damping
B68: Actual Damping | D68: Front Damping | E68: Rear Damping | G68: Front Damping | H68: Rear Damping | J68: Front | K68: Rear | L68: Front | M68: Rear
B69: =DAMPING!$Q$9*D18 -> 7.7756596 | C69: Ns/mm | D69: =B69*DAMPING!$Q$20/(DAMPING!$Q$20+DAMPING!$Q$21) -> 4.3475325 | E69: =B69*DAMPING!$Q$21/(DAMPING!$Q$20+DAMPING!$Q$21) -> 3.4281271 | F69: Ns/mm | G69: =D69/2 -> 2.1737663 | H69: =E69/2 -> 1.7140635 | I69: Ns/mm | J69: =G69*PI()/180*(FrontTrack/1000)^2*1000/2 -> 29.545367 | K69: =H69*PI()/180*(RearTrack/1000)^2*1000/2 -> 21.539558 | L69: =((PCx)/1000)^2*(G69*1000)*PI()/180*2 -> 21.522038 | M69: =((Wheelbase-PCx)/1000)^2*(H69*1000)*PI()/180*2 -> 61.328048 | N69: Nms/deg
B70: =DAMPING!$Q$18*E19 -> 4.2342073 | C70: Ns/mm | D70: =B70 -> 4.2342073 | E70: =D70*DAMPING!$Q$21/DAMPING!$Q$20 -> 3.3387676 | F70: Ns/mm | G70: =D70/2 -> 2.1171037 | H70: =E70/2 -> 1.6693838 | I70: Ns/mm | J70: =G70*PI()/180*(FrontTrack/1000)^2*1000/2 -> 28.775221 | K70: =H70*PI()/180*(RearTrack/1000)^2*1000/2 -> 20.978095 | L70: =((PCx)/1000)^2*(G70*1000)*PI()/180*2 -> 20.961032 | M70: =((Wheelbase-PCx)/1000)^2*(H70*1000)*PI()/180*2 -> 59.729437 | N70: Nms/deg
B71: =DAMPING!$Q$19*F20 -> 3.5337274 | C71: Ns/mm | D71: =E71/DAMPING!$Q$21*DAMPING!$Q$20 -> 4.4814544 | E71: =B71 -> 3.5337274 | F71: Ns/mm | G71: =D71/2 -> 2.2407272 | H71: =E71/2 -> 1.7668637 | I71: Ns/mm | J71: =G71*PI()/180*(FrontTrack/1000)^2*1000/2 -> 30.455485 | K71: =H71*PI()/180*(RearTrack/1000)^2*1000/2 -> 22.203064 | L71: =((PCx)/1000)^2*(G71*1000)*PI()/180*2 -> 22.185005 | M71: =((Wheelbase-PCx)/1000)^2*(H71*1000)*PI()/180*2 -> 63.217204 | N71: Nms/deg
B72: =DAMPING!$Q$27*G21 -> 78.007786 | C72: Nms/deg | D72: =G72*2 -> 6.6387763 | E72: =H72*2 -> 5.2348243 | F72: Ns/mm | G72: =J72*180/PI()*2/(FrontTrack/1000)^2/1000 -> 3.3193881 | H72: =K72*180/PI()*2/(RearTrack/1000)^2/1000 -> 2.6174121 | I72: Ns/mm | J72: =B72*DAMPING!$E$36/(DAMPING!$E$36+DAMPING!$E$37) -> 45.116415 | K72: =B72*DAMPING!$E$37/(DAMPING!$E$36+DAMPING!$E$37) -> 32.891371 | L72: =((PCx)/1000)^2*(G72*1000)*PI()/180*2 -> 32.864618 | M72: =((Wheelbase-PCx)/1000)^2*(H72*1000)*PI()/180*2 -> 93.649257 | N72: Nms/deg
B73: =DAMPING!$Q$33*H22 -> 247.06037 | C73: Nms/deg | D73: =G73*2 -> 12.964416 | E73: =H73*2 -> 10.222734 | F73: Ns/mm | G73: =L73*180/PI()/(PCx/1000)^2/1000/2 -> 6.4822082 | H73: =M73*180/PI()/((Wheelbase-PCx)/1000)^2/1000/2 -> 5.1113668 | I73: Ns/mm | J73: =G73*PI()/180*(FrontTrack/1000)^2*1000/2 -> 88.10479 | K73: =H73*PI()/180*(RearTrack/1000)^2*1000/2 -> 64.23133 | L73: =B73*(DAMPING!$E$38/(DAMPING!$E$39+DAMPING!$E$38)) -> 64.179085 | M73: =B73*DAMPING!$E$39/(DAMPING!$E$38+DAMPING!$E$39) -> 182.88129 | N73: Nms/deg
B74: =DAMPING!$Q$42*I23 -> 2.3449322 | C74: Ns/mm | D74: =G74*2 -> 4.6898643 | E74: =H74*2 -> 3.6980634 | F74: Ns/mm | G74: =B74 -> 2.3449322 | H74: =G74*DAMPING!Q45/DAMPING!Q44 -> 1.8490317 | I74: Ns/mm | J74: =G74*PI()/180*(FrontTrack/1000)^2*1000/2 -> 31.871817 | K74: =H74*PI()/180*(RearTrack/1000)^2*1000/2 -> 23.235617 | L74: =((PCx)/1000)^2*(G74*1000)*PI()/180*2 -> 23.216718 | M74: =((Wheelbase-PCx)/1000)^2*(H74*1000)*PI()/180*2 -> 66.157118 | N74: Nms/deg
B75: =DAMPING!$Q$43*J24 -> 2.2155595 | C75: Ns/mm | D75: =G75*2 -> 5.6195216 | E75: =H75*2 -> 4.431119 | F75: Ns/mm | G75: =H75*DAMPING!Q44/DAMPING!Q45 -> 2.8097608 | H75: =B75 -> 2.2155595 | I75: Ns/mm | J75: =G75*PI()/180*(FrontTrack/1000)^2*1000/2 -> 38.189669 | K75: =H75*PI()/180*(RearTrack/1000)^2*1000/2 -> 27.841542 | L75: =((PCx)/1000)^2*(G75*1000)*PI()/180*2 -> 27.818896 | M75: =((Wheelbase-PCx)/1000)^2*(H75*1000)*PI()/180*2 -> 79.27124 | N75: Nms/deg
